2025-06-03 21:03:45,040 - INFO - Session Replay for default trace: https://app.agentops.ai/sessions?trace_id=bdf889373a43c84f8ba85da2af948ecc
2025-06-03 21:04:48,156 - INFO - Session Replay for default.session trace: https://app.agentops.ai/sessions?trace_id=bdf889373a43c84f8ba85da2af948ecc
2025-06-03 21:05:27,429 - INFO - Session Replay for default.session trace: https://app.agentops.ai/sessions?trace_id=bdf889373a43c84f8ba85da2af948ecc
2025-06-03 21:05:35,927 - INFO - Session Replay for default.session trace: https://app.agentops.ai/sessions?trace_id=bdf889373a43c84f8ba85da2af948ecc
2025-06-03 21:06:02,656 - INFO - Session Replay for default.session trace: https://app.agentops.ai/sessions?trace_id=bdf889373a43c84f8ba85da2af948ecc
2025-06-03 21:07:51,543 - INFO - Session Replay for default.session trace: https://app.agentops.ai/sessions?trace_id=bdf889373a43c84f8ba85da2af948ecc
2025-06-03 21:09:09,688 - INFO - Session Replay for default.session trace: https://app.agentops.ai/sessions?trace_id=bdf889373a43c84f8ba85da2af948ecc
2025-06-03 21:33:55,097 - INFO - Session Replay for default.session trace: https://app.agentops.ai/sessions?trace_id=bdf889373a43c84f8ba85da2af948ecc
2025-06-03 21:38:53,572 - INFO - Session Replay for default.session trace: https://app.agentops.ai/sessions?trace_id=bdf889373a43c84f8ba85da2af948ecc
OR - Error in trace creation: litellm.AuthenticationError: AuthenticationError: OpenAIException - Incorrect API key provided: AIzaSyA6***************************3Jn8. You can find your API key at https://platform.openai.com/account/api-keys.
2025-06-03 21:15:36,289 - ERROR - Error in trace creation: litellm.AuthenticationError: AuthenticationError: OpenAIException - Incorrect API key provided: AIzaSyA6***************************3Jn8. You can find your API key at https://platform.openai.com/account/api-keys.
2025-06-03 21:15:36,290 - ERROR - Error in trace creation: litellm.AuthenticationError: AuthenticationError: OpenAIException - Incorrect API key provided: AIzaSyA6***************************3Jn8. You can find your API key at https://platform.openai.com/account/api-keys.
2025-06-03 21:16:05,342 - ERROR - Error in trace creation: litellm.NotFoundError: OpenAIException - The model `gpt-4` does not exist or you do not have access to it.
2025-06-03 21:16:05,344 - ERROR - Error in trace creation: litellm.NotFoundError: OpenAIException - The model `gpt-4` does not exist or you do not have access to it.
2025-06-03 21:16:05,345 - ERROR - Error in trace creation: litellm.NotFoundError: OpenAIException - The model `gpt-4` does not exist or you do not have access to it.
2025-06-03 21:16:05,346 - ERROR - Error in trace creation: litellm.NotFoundError: OpenAIException - The model `gpt-4` does not exist or you do not have access to it.
2025-06-03 21:16:34,776 - ERROR - Error in trace creation: litellm.RateLimitError: RateLimitError: OpenAIException - You exceeded your current quota, please check your plan and billing details. For more information on this error, read the docs: https://platform.openai.com/docs/guides/error-codes/api-errors.
2025-06-03 21:16:34,778 - ERROR - Error in trace creation: litellm.RateLimitError: RateLimitError: OpenAIException - You exceeded your current quota, please check your plan and billing details. For more information on this error, read the docs: https://platform.openai.com/docs/guides/error-codes/api-errors.
2025-06-03 21:16:34,780 - ERROR - Error in trace creation: litellm.RateLimitError: RateLimitError: OpenAIException - You exceeded your current quota, please check your plan and billing details. For more information on this error, read the docs: https://platform.openai.com/docs/guides/error-codes/api-errors.
2025-06-03 21:16:34,781 - ERROR - Error in trace creation: litellm.RateLimitError: RateLimitError: OpenAIException - You exceeded your current quota, please check your plan and billing details. For more information on this error, read the docs: https://platform.openai.com/docs/guides/error-codes/api-errors.
2025-06-03 21:18:00,486 - ERROR - Error in trace creation: litellm.RateLimitError: RateLimitError: OpenAIException - You exceeded your current quota, please check your plan and billing details. For more information on this error, read the docs: https://platform.openai.com/docs/guides/error-codes/api-errors.
2025-06-03 21:18:00,488 - ERROR - Error in trace creation: litellm.RateLimitError: RateLimitError: OpenAIException - You exceeded your current quota, please check your plan and billing details. For more information on this error, read the docs: https://platform.openai.com/docs/guides/error-codes/api-errors.
2025-06-03 21:18:00,490 - ERROR - Error in trace creation: litellm.RateLimitError: RateLimitError: OpenAIException - You exceeded your current quota, please check your plan and billing details. For more information on this error, read the docs: https://platform.openai.com/docs/guides/error-codes/api-errors.
2025-06-03 21:18:00,491 - ERROR - Error in trace creation: litellm.RateLimitError: RateLimitError: OpenAIException - You exceeded your current quota, please check your plan and billing details. For more information on this error, read the docs: https://platform.openai.com/docs/guides/error-codes/api-errors.
2025-06-03 21:18:39,841 - ERROR - Error in trace creation: litellm.NotFoundError: OpenAIException - The model `gpt-4-turbo` does not exist or you do not have access to it.
2025-06-03 21:18:39,843 - ERROR - Error in trace creation: litellm.NotFoundError: OpenAIException - The model `gpt-4-turbo` does not exist or you do not have access to it.
2025-06-03 21:18:39,844 - ERROR - Error in trace creation: litellm.NotFoundError: OpenAIException - The model `gpt-4-turbo` does not exist or you do not have access to it.
2025-06-03 21:18:39,845 - ERROR - Error in trace creation: litellm.NotFoundError: OpenAIException - The model `gpt-4-turbo` does not exist or you do not have access to it.
2025-06-03 21:19:04,620 - ERROR - Error in trace creation: litellm.NotFoundError: OpenAIException - The model `GPT-4` does not exist or you do not have access to it.
2025-06-03 21:19:04,621 - ERROR - Error in trace creation: litellm.NotFoundError: OpenAIException - The model `GPT-4` does not exist or you do not have access to it.
2025-06-03 21:19:04,621 - ERROR - Error in trace creation: litellm.NotFoundError: OpenAIException - The model `GPT-4` does not exist or you do not have access to it.
2025-06-03 21:19:04,622 - ERROR - Error in trace creation: litellm.NotFoundError: OpenAIException - The model `GPT-4` does not exist or you do not have access to it.
2025-06-03 21:45:26,548 - ERROR - Error in trace creation: litellm.NotFoundError: OpenAIException - The model `GPT-4` does not exist or you do not have access to it.
2025-06-03 21:45:26,550 - ERROR - Error in trace creation: litellm.NotFoundError: OpenAIException - The model `GPT-4` does not exist or you do not have access to it.
2025-06-03 21:45:26,551 - ERROR - Error in trace creation: litellm.NotFoundError: OpenAIException - The model `GPT-4` does not exist or you do not have access to it.
2025-06-03 21:45:26,551 - ERROR - Error in trace creation: litellm.NotFoundError: OpenAIException - The model `GPT-4` does not exist or you do not have access to it.
2025-06-03 21:45:41,038 - INFO - Session Replay for default.session trace: https://app.agentops.ai/sessions?trace_id=8b38f42e62f4d254c9105a0718c77bb2
2025-06-03 21:48:26,903 - INFO - Session Replay for default.session trace: https://app.agentops.ai/sessions?trace_id=8b38f42e62f4d254c9105a0718c77bb2
2025-06-03 21:53:51,495 - INFO - Session Replay for default.session trace: https://app.agentops.ai/sessions?trace_id=8b38f42e62f4d254c9105a0718c77bb2
2025-06-03 21:55:12,623 - INFO - Session Replay for default.session trace: https://app.agentops.ai/sessions?trace_id=8b38f42e62f4d254c9105a0718c77bb2
2025-06-03 21:56:23,409 - INFO - Session Replay for default.session trace: https://app.agentops.ai/sessions?trace_id=8b38f42e62f4d254c9105a0718c77bb2
2025-06-03 22:03:16,564 - INFO - Session Replay for default.session trace: https://app.agentops.ai/sessions?trace_id=8b38f42e62f4d254c9105a0718c77bb2
2025-06-04 23:16:24,948 - INFO - Session Replay for default.session trace: https://app.agentops.ai/sessions?trace_id=8b38f42e62f4d254c9105a0718c77bb2
